Workbook

Sheet Posts
A1: Post ID | B1: Platform_Clean | C1: Data | D1: Campaign_Name | E1: Content Type | F1: Post Text | G1: Likes | H1: Shares | I1: Comments | J1: Impressions | K1: Reach | L1: Clicks | M1: Hashtag_Clean_1 | N1: hashtag_clean2 | O1: hashtag_clean3 | P1: Engagement_Rate | Q1: Post_Date_Num | R1: Total_Engagement | S1: Period_Type | T1: Follower_Growth | U1: Week
A2: P070 | B2: FACEBOOK | C2: 45749 | D2: =IF( AND(C2 >= 'Campaign Metadata'!J$2, C2 <= 'Campaign Metadata'!H$2), 'Campaign Metadata'!A$2, IF( AND(C2 >= 'Campaign Metadata'!J$3, C2 <= 'Campaign Metadata'!H$3), 'Campaign Metadata'!A$3, IF( AND(C2 >= 'Campaign Metadata'!J$4, C2 <= 'Campaign Metadata'!H$4), 'Campaign Metadata'!A$4, IF( AND(C2 >= 'Campaign Metadata'!J$5, C2 <= 'Campaign Metadata'!H$5), 'Campaign Metadata'!A$5, "Outside Campaign" )))) -> Outside Campaign | E2: Video | F2: Check out our latest video on facebook! | G2: 199 | H2: 772 | I2: 400 | J2: 3582 | K2: 2988 | L2: 43 | M2: PepsiCoRefresh | P2: 0.38274707 | Q2: =DATEVALUE(C2) -> 45749 | R2: =G2 + H2 + I2 -> 1371 | S2: =IF(D2="Outside Campaign","Before Campaign","During Campaign") -> Before Campaign | T2: =IF(B2=B1, K2-K1, 0) -> 0 | U2: =ISOWEEKNUM(C2) -> 14
A3: P224 | B3: FACEBOOK | C3: 45790 | D3: =IF( AND(C3 >= 'Campaign Metadata'!J$2, C3 <= 'Campaign Metadata'!H$2), 'Campaign Metadata'!A$2, IF( AND(C3 >= 'Campaign Metadata'!J$3, C3 <= 'Campaign Metadata'!H$3), 'Campaign Metadata'!A$3, IF( AND(C3 >= 'Campaign Metadata'!J$4, C3 <= 'Campaign Metadata'!H$4), 'Campaign Metadata'!A$4, IF( AND(C3 >= 'Campaign Metadata'!J$5, C3 <= 'Campaign Metadata'!H$5), 'Campaign Metadata'!A$5, "Outside Campaign" )))) -> Outside Campaign | E3: Image | F3: Check out our latest image on facebook! | G3: 602 | H3: 594 | I3: 156 | J3: 4214 | K3: 3363 | L3: 164 | M3: PepsiCoRefresh | P3: 0.32083531 | Q3: =DATEVALUE(C3) -> 45790 | R3: =G3 + H3 + I3 -> 1352 | S3: =IF(D3="Outside Campaign","Before Campaign","During Campaign") -> Before Campaign | T3: =IF(B3=B2, K3-K2, 0) -> 375 | U3: =ISOWEEKNUM(C3) -> 20
A4: P248 | B4: FACEBOOK | C4: 45690 | D4: =IF( AND(C4 >= 'Campaign Metadata'!J$2, C4 <= 'Campaign Metadata'!H$2), 'Campaign Metadata'!A$2, IF( AND(C4 >= 'Campaign Metadata'!J$3, C4 <= 'Campaign Metadata'!H$3), 'Campaign Metadata'!A$3, IF( AND(C4 >= 'Campaign Metadata'!J$4, C4 <= 'Campaign Metadata'!H$4), 'Campaign Metadata'!A$4, IF( AND(C4 >= 'Campaign Metadata'!J$5, C4 <= 'Campaign Metadata'!H$5), 'Campaign Metadata'!A$5, "Outside Campaign" )))) -> NewYearRefresh | E4: Story | F4: Check out our latest story on facebook! | G4: 886 | H4: 126 | I4: 153 | J4: 4430 | K4: 4037 | L4: 212 | M4: ThirstyForMore | P4: 0.26297968 | Q4: =DATEVALUE(C4) -> 45690 | R4: =G4 + H4 + I4 -> 1165 | S4: =IF(D4="Outside Campaign","Before Campaign","During Campaign") -> During Campaign | T4: =IF(B4=B3, K4-K3, 0) -> 674 | U4: =ISOWEEKNUM(C4) -> 5
A5: P259 | B5: FACEBOOK | C5: 45698 | D5: =IF( AND(C5 >= 'Campaign Metadata'!J$2, C5 <= 'Campaign Metadata'!H$2), 'Campaign Metadata'!A$2, IF( AND(C5 >= 'Campaign Metadata'!J$3, C5 <= 'Campaign Metadata'!H$3), 'Campaign Metadata'!A$3, IF( AND(C5 >= 'Campaign Metadata'!J$4, C5 <= 'Campaign Metadata'!H$4), 'Campaign Metadata'!A$4, IF( AND(C5 >= 'Campaign Metadata'!J$5, C5 <= 'Campaign Metadata'!H$5), 'Campaign Metadata'!A$5, "Outside Campaign" )))) -> NewYearRefresh | E5: Text | F5: Check out our latest text on facebook! | G5: 562 | H5: 158 | I5: 149 | J5: 3372 | K5: 2940 | L5: 93 | M5: PepsiCoRefresh | P5: 0.25771056 | Q5: =DATEVALUE(C5) -> 45698 | R5: =G5 + H5 + I5 -> 869 | S5: =IF(D5="Outside Campaign","Before Campaign","During Campaign") -> During Campaign | T5: =IF(B5=B4, K5-K4, 0) -> -1097 | U5: =ISOWEEKNUM(C5) -> 7
A6: P277 | B6: FACEBOOK | C6: 45753 | D6: =IF( AND(C6 >= 'Campaign Metadata'!J$2, C6 <= 'Campaign Metadata'!H$2), 'Campaign Metadata'!A$2, IF( AND(C6 >= 'Campaign Metadata'!J$3, C6 <= 'Campaign Metadata'!H$3), 'Campaign Metadata'!A$3, IF( AND(C6 >= 'Campaign Metadata'!J$4, C6 <= 'Campaign Metadata'!H$4), 'Campaign Metadata'!A$4, IF( AND(C6 >= 'Campaign Metadata'!J$5, C6 <= 'Campaign Metadata'!H$5), 'Campaign Metadata'!A$5, "Outside Campaign" )))) -> Outside Campaign | E6: Image | F6: Check out our latest image on facebook! | G6: 4236 | H6: 711 | I6: 298 | J6: 21180 | K6: 20516 | L6: 238 | M6: LiveForNow | P6: 0.24763928 | Q6: =DATEVALUE(C6) -> 45753 | R6: =G6 + H6 + I6 -> 5245 | S6: =IF(D6="Outside Campaign","Before Campaign","During Campaign") -> Before Campaign | T6: =IF(B6=B5, K6-K5, 0) -> 17576 | U6: =ISOWEEKNUM(C6) -> 14
A7: P246 | B7: FACEBOOK | C7: 45576 | D7: =IF( AND(C7 >= 'Campaign Metadata'!J$2, C7 <= 'Campaign Metadata'!H$2), 'Campaign Metadata'!A$2, IF( AND(C7 >= 'Campaign Metadata'!J$3, C7 <= 'Campaign Metadata'!H$3), 'Campaign Metadata'!A$3, IF( AND(C7 >= 'Campaign Metadata'!J$4, C7 <= 'Campaign Metadata'!H$4), 'Campaign Metadata'!A$4, IF( AND(C7 >= 'Campaign Metadata'!J$5, C7 <= 'Campaign Metadata'!H$5), 'Campaign Metadata'!A$5, "Outside Campaign" )))) -> FestiveRadiance | E7: Image | F7: Check out our latest image on facebook! | G7: 400 | H7: 680 | I7: 434 | J7: 6400 | K7: 5472 | L7: 160 | M7: LiveForNow | P7: 0.2365625 | Q7: =DATEVALUE(C7) -> 45576 | R7: =G7 + H7 + I7 -> 1514 | S7: =IF(D7="Outside Campaign","Before Campaign","During Campaign") -> During Campaign | T7: =IF(B7=B6, K7-K6, 0) -> -15044 | U7: =ISOWEEKNUM(C7) -> 41
A8: P120 | B8: FACEBOOK | C8: 45586 | D8: =IF( AND(C8 >= 'Campaign Metadata'!J$2, C8 <= 'Campaign Metadata'!H$2), 'Campaign Metadata'!A$2, IF( AND(C8 >= 'Campaign Metadata'!J$3, C8 <= 'Campaign Metadata'!H$3), 'Campaign Metadata'!A$3, IF( AND(C8 >= 'Campaign Metadata'!J$4, C8 <= 'Campaign Metadata'!H$4), 'Campaign Metadata'!A$4, IF( AND(C8 >= 'Campaign Metadata'!J$5, C8 <= 'Campaign Metadata'!H$5), 'Campaign Metadata'!A$5, "Outside Campaign" )))) -> FestiveRadiance | E8: Story | F8: Check out our latest story on facebook! | G8: 780 | H8: 928 | I8: 301 | J8: 8580 | K8: 8081 | L8: 91 | M8: ThirstyForMore | P8: 0.23414918 | Q8: =DATEVALUE(C8) -> 45586 | R8: =G8 + H8 + I8 -> 2009 | S8: =IF(D8="Outside Campaign","Before Campaign","During Campaign") -> During Campaign | T8: =IF(B8=B7, K8-K7, 0) -> 2609 | U8: =ISOWEEKNUM(C8) -> 43
A9: P159 | B9: FACEBOOK | C9: 45621 | D9: =IF( AND(C9 >= 'Campaign Metadata'!J$2, C9 <= 'Campaign Metadata'!H$2), 'Campaign Metadata'!A$2, IF( AND(C9 >= 'Campaign Metadata'!J$3, C9 <= 'Campaign Metadata'!H$3), 'Campaign Metadata'!A$3, IF( AND(C9 >= 'Campaign Metadata'!J$4, C9 <= 'Campaign Metadata'!H$4), 'Campaign Metadata'!A$4, IF( AND(C9 >= 'Campaign Metadata'!J$5, C9 <= 'Campaign Metadata'!H$5), 'Campaign Metadata'!A$5, "Outside Campaign" )))) -> FestiveRadiance | E9: Story | F9: Check out our latest story on facebook! | G9: 2120 | H9: 158 | I9: 488 | J9: 12720 | K9: 12085 | L9: 17 | M9: LiveForNow | P9: 0.21745283 | Q9: =DATEVALUE(C9) -> 45621 | R9: =G9 + H9 + I9 -> 2766 | S9: =IF(D9="Outside Campaign","Before Campaign","During Campaign") -> During Campaign | T9: =IF(B9=B8, K9-K8, 0) -> 4004 | U9: =ISOWEEKNUM(C9) -> 48
A10: P137 | B10: FACEBOOK | C10: 45504 | D10: =IF( AND(C10 >= 'Campaign Metadata'!J$2, C10 <= 'Campaign Metadata'!H$2), 'Campaign Metadata'!A$2, IF( AND(C10 >= 'Campaign Metadata'!J$3, C10 <= 'Campaign Metadata'!H$3), 'Campaign Metadata'!A$3, IF( AND(C10 >= 'Campaign Metadata'!J$4, C10 <= 'Campaign Metadata'!H$4), 'Campaign Metadata'!A$4, IF( AND(C10 >= 'Campaign Metadata'!J$5, C10 <= 'Campaign Metadata'!H$5), 'Campaign Metadata'!A$5, "Outside Campaign" )))) -> SummerSplash | E10: Video | F10: Check out our latest video on facebook! | G10: 3008 | H10: 94 | I10: 37 | J10: 15040 | K10: 14639 | L10: 277 | M10: LiveForNow | P10: 0.20871011 | Q10: =DATEVALUE(C10) -> 45504 | R10: =G10 + H10 + I10 -> 3139 | S10: =IF(D10="Outside Campaign","Before Campaign","During Campaign") -> During Campaign | T10: =IF(B10=B9, K10-K9, 0) -> 2554 | U10: =ISOWEEKNUM(C10) -> 31
A11: P077 | B11: FACEBOOK | C11: 45720 | D11: =IF( AND(C11 >= 'Campaign Metadata'!J$2, C11 <= 'Campaign Metadata'!H$2), 'Campaign Metadata'!A$2, IF( AND(C11 >= 'Campaign Metadata'!J$3, C11 <= 'Campaign Metadata'!H$3), 'Campaign Metadata'!A$3, IF( AND(C11 >= 'Campaign Metadata'!J$4, C11 <= 'Campaign Metadata'!H$4), 'Campaign Metadata'!A$4, IF( AND(C11 >= 'Campaign Metadata'!J$5, C11 <= 'Campaign Metadata'!H$5), 'Campaign Metadata'!A$5, "Outside Campaign" )))) -> Outside Campaign | E11: Story | F11: Check out our latest story on facebook! | G11: 1249 | H11: 116 | I11: 420 | J11: 8743 | K11: 8538 | L11: 63 | M11: PepsiCoRefresh | P11: 0.20416333 | Q11: =DATEVALUE(C11) -> 45720 | R11: =G11 + H11 + I11 -> 1785 | S11: =IF(D11="Outside Campaign","Before Campaign","During Campaign") -> Before Campaign | T11: =IF(B11=B10, K11-K10, 0) -> -6101 | U11: =ISOWEEKNUM(C11) -> 10
A12: P152 | B12: FACEBOOK | C12: 45769 | D12: =IF( AND(C12 >= 'Campaign Metadata'!J$2, C12 <= 'Campaign Metadata'!H$2), 'Campaign Metadata'!A$2, IF( AND(C12 >= 'Campaign Metadata'!J$3, C12 <= 'Campaign Metadata'!H$3), 'Campaign Metadata'!A$3, IF( AND(C12 >= 'Campaign Metadata'!J$4, C12 <= 'Campaign Metadata'!H$4), 'Campaign Metadata'!A$4, IF( AND(C12 >= 'Campaign Metadata'!J$5, C12 <= 'Campaign Metadata'!H$5), 'Campaign Metadata'!A$5, "Outside Campaign" )))) -> Outside Campaign | E12: Image | F12: Check out our latest image on facebook! | G12: 4804 | H12: 550 | I12: 270 | J12: 28824 | K12: 28370 | L12: 47 | M12: ThirstyForMore | P12: 0.19511518 | Q12: =DATEVALUE(C12) -> 45769 | R12: =G12 + H12 + I12 -> 5624 | S12: =IF(D12="Outside Campaign","Before Campaign","During Campaign") -> Before Campaign | T12: =IF(B12=B11, K12-K11, 0) -> 19832 | U12: =ISOWEEKNUM(C12) -> 17
A13: P218 | B13: FACEBOOK | C13: 45454 | D13: =IF( AND(C13 >= 'Campaign Metadata'!J$2, C13 <= 'Campaign Metadata'!H$2), 'Campaign Metadata'!A$2, IF( AND(C13 >= 'Campaign Metadata'!J$3, C13 <= 'Campaign Metadata'!H$3), 'Campaign Metadata'!A$3, IF( AND(C13 >= 'Campaign Metadata'!J$4, C13 <= 'Campaign Metadata'!H$4), 'Campaign Metadata'!A$4, IF( AND(C13 >= 'Campaign Metadata'!J$5, C13 <= 'Campaign Metadata'!H$5), 'Campaign Metadata'!A$5, "Outside Campaign" )))) -> SummerSplash | E13: Carousel | F13: Check out our latest carousel on facebook! | G13: 1869 | H13: 453 | I13: 490 | J13: 14952 | K13: 14309 | L13: 275 | M13: PepsiCoRefresh | P13: 0.18806849 | Q13: =DATEVALUE(C13) -> 45454 | R13: =G13 + H13 + I13 -> 2812 | S13: =IF(D13="Outside Campaign","Before Campaign","During Campaign") -> During Campaign | T13: =IF(B13=B12, K13-K12, 0) -> -14061 | U13: =ISOWEEKNUM(C13) -> 24
... A22: P052 | B22: FACEBOOK | C22: 45660 | D22: =IF( AND(C22 >= 'Campaign Metadata'!J$2, C22 <= 'Campaign Metadata'!H$2), 'Campaign Metadata'!A$2, IF( AND(C22 >= 'Campaign Metadata'!J$3, C22 <= 'Campaign Metadata'!H$3), 'Campaign Metadata'!A$3, IF( AND(C22 >= 'Campaign Metadata'!J$4, C22 <= 'Campaign Metadata'!H$4), 'Campaign Metadata'!A$4, IF( AND(C22 >= 'Campaign Metadata'!J$5, C22 <= 'Campaign Metadata'!H$5), 'Campaign Metadata'!A$5, "Outside Campaign" )))) -> NewYearRefresh | E22: Image | F22: Check out our latest image on facebook! | G22: 947 | H22: 338 | I22: 350 | J22: 10417 | K22: 9730 | L22: 34 | M22: PepsiCoRefresh | P22: 0.15695498 | Q22: =DATEVALUE(C22) -> 45660 | R22: =G22 + H22 + I22 -> 1635 | S22: =IF(D22="Outside Campaign","Before Campaign","During Campaign") -> During Campaign | T22: =IF(B22=B21, K22-K21, 0) -> -6579 | U22: =ISOWEEKNUM(C22) -> 1
A23: P140 | B23: FACEBOOK | C23: 45488 | D23: =IF( AND(C23 >= 'Campaign Metadata'!J$2, C23 <= 'Campaign Metadata'!H$2), 'Campaign Metadata'!A$2, IF( AND(C23 >= 'Campaign Metadata'!J$3, C23 <= 'Campaign Metadata'!H$3), 'Campaign Metadata'!A$3, IF( AND(C23 >= 'Campaign Metadata'!J$4, C23 <= 'Campaign Metadata'!H$4), 'Campaign Metadata'!A$4, IF( AND(C23 >= 'Campaign Metadata'!J$5, C23 <= 'Campaign Metadata'!H$5), 'Campaign Metadata'!A$5, "Outside Campaign" )))) -> SummerSplash | E23: Image | F23: Check out our latest image on facebook! | G23: 2291 | H23: 78 | I23: 485 | J23: 18328 | K23: 18101 | L23: 10 | M23: ThirstyForMore | N23: SmoothLikeNitroPepsi | P23: 0.15571803 | Q23: =DATEVALUE(C23) -> 45488 | R23: =G23 + H23 + I23 -> 2854 | S23: =IF(D23="Outside Campaign","Before Campaign","During Campaign") -> During Campaign | T23: =IF(B23=B22, K23-K22, 0) -> 8371 | U23: =ISOWEEKNUM(C23) -> 29
A24: P014 | B24: FACEBOOK | C24: 45704 | D24: =IF( AND(C24 >= 'Campaign Metadata'!J$2, C24 <= 'Campaign Metadata'!H$2), 'Campaign Metadata'!A$2, IF( AND(C24 >= 'Campaign Metadata'!J$3, C24 <= 'Campaign Metadata'!H$3), 'Campaign Metadata'!A$3, IF( AND(C24 >= 'Campaign Metadata'!J$4, C24 <= 'Campaign Metadata'!H$4), 'Campaign Metadata'!A$4, IF( AND(C24 >= 'Campaign Metadata'!J$5, C24 <= 'Campaign Metadata'!H$5), 'Campaign Metadata'!A$5, "Outside Campaign" )))) -> NewYearRefresh | E24: Story | F24: Check out our latest story on facebook! | G24: 4242 | H24: 555 | I24: 131 | J24: 33936 | K24: 33802 | L24: 265 | M24: LiveForNow | P24: 0.14521452 | Q24: =DATEVALUE(C24) -> 45704 | R24: =G24 + H24 + I24 -> 4928 | S24: =IF(D24="Outside Campaign","Before Campaign","During Campaign") -> During Campaign | T24: =IF(B24=B23, K24-K23, 0) -> 15701 | U24: =ISOWEEKNUM(C24) -> 7
A25: P299 | B25: FACEBOOK | C25: 45530 | D25: =IF( AND(C25 >= 'Campaign Metadata'!J$2, C25 <= 'Campaign Metadata'!H$2), 'Campaign Metadata'!A$2, IF( AND(C25 >= 'Campaign Metadata'!J$3, C25 <= 'Campaign Metadata'!H$3), 'Campaign Metadata'!A$3, IF( AND(C25 >= 'Campaign Metadata'!J$4, C25 <= 'Campaign Metadata'!H$4), 'Campaign Metadata'!A$4, IF( AND(C25 >= 'Campaign Metadata'!J$5, C25 <= 'Campaign Metadata'!H$5), 'Campaign Metadata'!A$5, "Outside Campaign" )))) -> SummerSplash | E25: Image | F25: Check out our latest image on facebook! | G25: 2581 | H25: 517 | I25: 117 | J25: 23229 | K25: 22331 | L25: 70 | M25: LiveForNow | P25: 0.13840458 | Q25: =DATEVALUE(C25) -> 45530 | R25: =G25 + H25 + I25 -> 3215 | S25: =IF(D25="Outside Campaign","Before Campaign","During Campaign") -> During Campaign | T25: =IF(B25=B24, K25-K24, 0) -> -11471 | U25: =ISOWEEKNUM(C25) -> 35
A26: P174 | B26: FACEBOOK | C26: 45465 | D26: =IF( AND(C26 >= 'Campaign Metadata'!J$2, C26 <= 'Campaign Metadata'!H$2), 'Campaign Metadata'!A$2, IF( AND(C26 >= 'Campaign Metadata'!J$3, C26 <= 'Campaign Metadata'!H$3), 'Campaign Metadata'!A$3, IF( AND(C26 >= 'Campaign Metadata'!J$4, C26 <= 'Campaign Metadata'!H$4), 'Campaign Metadata'!A$4, IF( AND(C26 >= 'Campaign Metadata'!J$5, C26 <= 'Campaign Metadata'!H$5), 'Campaign Metadata'!A$5, "Outside Campaign" )))) -> SummerSplash | E26: Text | F26: Check out our latest text on facebook! | G26: 3828 | H26: 148 | I26: 253 | J26: 30624 | K26: 30229 | L26: 235 | M26: ThirstyForMore | P26: 0.13809431 | Q26: =DATEVALUE(C26) -> 45465 | R26: =G26 + H26 + I26 -> 4229 | S26: =IF(D26="Outside Campaign","Before Campaign","During Campaign") -> During Campaign | T26: =IF(B26=B25, K26-K25, 0) -> 7898 | U26: =ISOWEEKNUM(C26) -> 25
A27: P088 | B27: FACEBOOK | C27: 45480 | D27: =IF( AND(C27 >= 'Campaign Metadata'!J$2, C27 <= 'Campaign Metadata'!H$2), 'Campaign Metadata'!A$2, IF( AND(C27 >= 'Campaign Metadata'!J$3, C27 <= 'Campaign Metadata'!H$3), 'Campaign Metadata'!A$3, IF( AND(C27 >= 'Campaign Metadata'!J$4, C27 <= 'Campaign Metadata'!H$4), 'Campaign Metadata'!A$4, IF( AND(C27 >= 'Campaign Metadata'!J$5, C27 <= 'Campaign Metadata'!H$5), 'Campaign Metadata'!A$5, "Outside Campaign" )))) -> SummerSplash | E27: Story | F27: Check out our latest story on facebook! | G27: 302 | H27: 47 | I27: 430 | J27: 5738 | K27: 4890 | L27: 25 | M27: PepsiCoRefresh | P27: 0.13576159 | Q27: =DATEVALUE(C27) -> 45480 | R27: =G27 + H27 + I27 -> 779 | S27: =IF(D27="Outside Campaign","Before Campaign","During Campaign") -> During Campaign | T27: =IF(B27=B26, K27-K26, 0) -> -25339 | U27: =ISOWEEKNUM(C27) -> 27
A28: P236 | B28: FACEBOOK | C28: 45523 | D28: =IF( AND(C28 >= 'Campaign Metadata'!J$2, C28 <= 'Campaign Metadata'!H$2), 'Campaign Metadata'!A$2, IF( AND(C28 >= 'Campaign Metadata'!J$3, C28 <= 'Campaign Metadata'!H$3), 'Campaign Metadata'!A$3, IF( AND(C28 >= 'Campaign Metadata'!J$4, C28 <= 'Campaign Metadata'!H$4), 'Campaign Metadata'!A$4, IF( AND(C28 >= 'Campaign Metadata'!J$5, C28 <= 'Campaign Metadata'!H$5), 'Campaign Metadata'!A$5, "Outside Campaign" )))) -> SummerSplash | E28: Text | F28: Check out our latest text on facebook! | G28: 1257 | H28: 19 | I28: 351 | J28: 12570 | K28: 11660 | L28: 194 | M28: LiveForNow | N28: AnytimeIsPepsiTime | O28: ThirstyForMore | P28: 0.12943516 | Q28: =DATEVALUE(C28) -> 45523 | R28: =G28 + H28 + I28 -> 1627 | S28: =IF(D28="Outside Campaign","Before Campaign","During Campaign") -> During Campaign | T28: =IF(B28=B27, K28-K27, 0) -> 6770 | U28: =ISOWEEKNUM(C28) -> 34
A29: P056 | B29: FACEBOOK | C29: 45644 | D29: =IF( AND(C29 >= 'Campaign Metadata'!J$2, C29 <= 'Campaign Metadata'!H$2), 'Campaign Metadata'!A$2, IF( AND(C29 >= 'Campaign Metadata'!J$3, C29 <= 'Campaign Metadata'!H$3), 'Campaign Metadata'!A$3, IF( AND(C29 >= 'Campaign Metadata'!J$4, C29 <= 'Campaign Metadata'!H$4), 'Campaign Metadata'!A$4, IF( AND(C29 >= 'Campaign Metadata'!J$5, C29 <= 'Campaign Metadata'!H$5), 'Campaign Metadata'!A$5, "Outside Campaign" )))) -> FestiveRadiance | E29: Carousel | F29: Check out our latest carousel on facebook! | G29: 2946 | H29: 498 | I29: 367 | J29: 29460 | K29: 28527 | L29: 60 | M29: LiveForNow | P29: 0.12936185 | Q29: =DATEVALUE(C29) -> 45644 | R29: =G29 + H29 + I29 -> 3811 | S29: =IF(D29="Outside Campaign","Before Campaign","During Campaign") -> During Campaign | T29: =IF(B29=B28, K29-K28, 0) -> 16867 | U29: =ISOWEEKNUM(C29) -> 51
A30: P012 | B30: FACEBOOK | C30: 45494 | D30: =IF( AND(C30 >= 'Campaign Metadata'!J$2, C30 <= 'Campaign Metadata'!H$2), 'Campaign Metadata'!A$2, IF( AND(C30 >= 'Campaign Metadata'!J$3, C30 <= 'Campaign Metadata'!H$3), 'Campaign Metadata'!A$3, IF( AND(C30 >= 'Campaign Metadata'!J$4, C30 <= 'Campaign Metadata'!H$4), 'Campaign Metadata'!A$4, IF( AND(C30 >= 'Campaign Metadata'!J$5, C30 <= 'Campaign Metadata'!H$5), 'Campaign Metadata'!A$5, "Outside Campaign" )))) -> SummerSplash | E30: Reel | F30: Check out our latest reel on facebook! | G30: 1946 | H30: 686 | I30: 377 | J30: 23352 | K30: 22982 | L30: 213 | M30: LiveForNow | P30: 0.12885406 | Q30: =DATEVALUE(C30) -> 45494 | R30: =G30 + H30 + I30 -> 3009 | S30: =IF(D30="Outside Campaign","Before Campaign","During Campaign") -> During Campaign | T30: =IF(B30=B29, K30-K29, 0) -> -5545 | U30: =ISOWEEKNUM(C30) -> 29
A31: P235 | B31: FACEBOOK | C31: 45648 | D31: =IF( AND(C31 >= 'Campaign Metadata'!J$2, C31 <= 'Campaign Metadata'!H$2), 'Campaign Metadata'!A$2, IF( AND(C31 >= 'Campaign Metadata'!J$3, C31 <= 'Campaign Metadata'!H$3), 'Campaign Metadata'!A$3, IF( AND(C31 >= 'Campaign Metadata'!J$4, C31 <= 'Campaign Metadata'!H$4), 'Campaign Metadata'!A$4, IF( AND(C31 >= 'Campaign Metadata'!J$5, C31 <= 'Campaign Metadata'!H$5), 'Campaign Metadata'!A$5, "Outside Campaign" )))) -> FestiveRadiance | E31: Image | F31: Check out our latest image on facebook! | G31: 3196 | H31: 941 | I31: 376 | J31: 35156 | K31: 34444 | L31: 241 | M31: PepsiCoRefresh | P31: 0.12837069 | Q31: =DATEVALUE(C31) -> 45648 | R31: =G31 + H31 + I31 -> 4513 | S31: =IF(D31="Outside Campaign","Before Campaign","During Campaign") -> During Campaign | T31: =IF(B31=B30, K31-K30, 0) -> 11462 | U31: =ISOWEEKNUM(C31) -> 51
A32: P033 | B32: FACEBOOK | C32: 45525 | D32: =IF( AND(C32 >= 'Campaign Metadata'!J$2, C32 <= 'Campaign Metadata'!H$2), 'Campaign Metadata'!A$2, IF( AND(C32 >= 'Campaign Metadata'!J$3, C32 <= 'Campaign Metadata'!H$3), 'Campaign Metadata'!A$3, IF( AND(C32 >= 'Campaign Metadata'!J$4, C32 <= 'Campaign Metadata'!H$4), 'Campaign Metadata'!A$4, IF( AND(C32 >= 'Campaign Metadata'!J$5, C32 <= 'Campaign Metadata'!H$5), 'Campaign Metadata'!A$5, "Outside Campaign" )))) -> SummerSplash | E32: Image | F32: Check out our latest image on facebook! | G32: 1407 | H32: 400 | I32: 351 | J32: 16884 | K32: 15954 | L32: 113 | M32: PepsiCoRefresh | P32: 0.12781331 | Q32: =DATEVALUE(C32) -> 45525 | R32: =G32 + H32 + I32 -> 2158 | S32: =IF(D32="Outside Campaign","Before Campaign","During Campaign") -> During Campaign | T32: =IF(B32=B31, K32-K31, 0) -> -18490 | U32: =ISOWEEKNUM(C32) -> 34
A33: P293 | B33: FACEBOOK | C33: 45791 | D33: =IF( AND(C33 >= 'Campaign Metadata'!J$2, C33 <= 'Campaign Metadata'!H$2), 'Campaign Metadata'!A$2, IF( AND(C33 >= 'Campaign Metadata'!J$3, C33 <= 'Campaign Metadata'!H$3), 'Campaign Metadata'!A$3, IF( AND(C33 >= 'Campaign Metadata'!J$4, C33 <= 'Campaign Metadata'!H$4), 'Campaign Metadata'!A$4, IF( AND(C33 >= 'Campaign Metadata'!J$5, C33 <= 'Campaign Metadata'!H$5), 'Campaign Metadata'!A$5, "Outside Campaign" )))) -> Outside Campaign | E33: Text | F33: Check out our latest text on facebook! | G33: 2634 | H33: 726 | I33: 241 | J33: 28974 | K33: 28102 | L33: 277 | M33: ThirstyForMore | P33: 0.12428384 | Q33: =DATEVALUE(C33) -> 45791 | R33: =G33 + H33 + I33 -> 3601 | S33: =IF(D33="Outside Campaign","Before Campaign","During Campaign") -> Before Campaign | T33: =IF(B33=B32, K33-K32, 0) -> 12148 | U33: =ISOWEEKNUM(C33) -> 20
A34: P292 | B34: FACEBOOK | C34: 45613 | D34: =IF( AND(C34 >= 'Campaign Metadata'!J$2, C34 <= 'Campaign Metadata'!H$2), 'Campaign Metadata'!A$2, IF( AND(C34 >= 'Campaign Metadata'!J$3, C34 <= 'Campaign Metadata'!H$3), 'Campaign Metadata'!A$3, IF( AND(C34 >= 'Campaign Metadata'!J$4, C34 <= 'Campaign Metadata'!H$4), 'Campaign Metadata'!A$4, IF( AND(C34 >= 'Campaign Metadata'!J$5, C34 <= 'Campaign Metadata'!H$5), 'Campaign Metadata'!A$5, "Outside Campaign" )))) -> FestiveRadiance | E34: Text | F34: Check out our latest text on facebook! | G34: 880 | H34: 297 | I34: 345 | J34: 12320 | K34: 11978 | L34: 238 | M34: PepsiCoRefresh | N34: AnytimeIsPepsiTime | P34: 0.12353896 | Q34: =DATEVALUE(C34) -> 45613 | R34: =G34 + H34 + I34 -> 1522 | S34: =IF(D34="Outside Campaign","Before Campaign","During Campaign") -> During Campaign | T34: =IF(B34=B33, K34-K33, 0) -> -16124 | U34: =ISOWEEKNUM(C34) -> 46
A35: P245 | B35: FACEBOOK | C35: 45669 | D35: =IF( AND(C35 >= 'Campaign Metadata'!J$2, C35 <= 'Campaign Metadata'!H$2), 'Campaign Metadata'!A$2, IF( AND(C35 >= 'Campaign Metadata'!J$3, C35 <= 'Campaign Metadata'!H$3), 'Campaign Metadata'!A$3, IF( AND(C35 >= 'Campaign Metadata'!J$4, C35 <= 'Campaign Metadata'!H$4), 'Campaign Metadata'!A$4, IF( AND(C35 >= 'Campaign Metadata'!J$5, C35 <= 'Campaign Metadata'!H$5), 'Campaign Metadata'!A$5, "Outside Campaign" )))) -> NewYearRefresh | E35: Reel | F35: Check out our latest reel on facebook! | G35: 4134 | H35: 824 | I35: 99 | J35: 41340 | K35: 41050 | L35: 177 | M35: ThirstyForMore | P35: 0.12232704 | Q35: =DATEVALUE(C35) -> 45669 | R35: =G35 + H35 + I35 -> 5057 | S35: =IF(D35="Outside Campaign","Before Campaign","During Campaign") -> During Campaign | T35: =IF(B35=B34, K35-K34, 0) -> 29072 | U35: =ISOWEEKNUM(C35) -> 2
A36: P255 | B36: FACEBOOK | C36: 45750 | D36: =IF( AND(C36 >= 'Campaign Metadata'!J$2, C36 <= 'Campaign Metadata'!H$2), 'Campaign Metadata'!A$2, IF( AND(C36 >= 'Campaign Metadata'!J$3, C36 <= 'Campaign Metadata'!H$3), 'Campaign Metadata'!A$3, IF( AND(C36 >= 'Campaign Metadata'!J$4, C36 <= 'Campaign Metadata'!H$4), 'Campaign Metadata'!A$4, IF( AND(C36 >= 'Campaign Metadata'!J$5, C36 <= 'Campaign Metadata'!H$5), 'Campaign Metadata'!A$5, "Outside Campaign" )))) -> Outside Campaign | E36: Story | F36: Check out our latest story on facebook! | G36: 3767 | H36: 514 | I36: 238 | J36: 37670 | K36: 36807 | L36: 226 | M36: LiveForNow | P36: 0.11996284 | Q36: =DATEVALUE(C36) -> 45750 | R36: =G36 + H36 + I36 -> 4519 | S36: =IF(D36="Outside Campaign","Before Campaign","During Campaign") -> Before Campaign | T36: =IF(B36=B35, K36-K35, 0) -> -4243 | U36: =ISOWEEKNUM(C36) -> 14
A37: P247 | B37: FACEBOOK | C37: 45531 | D37: =IF( AND(C37 >= 'Campaign Metadata'!J$2, C37 <= 'Campaign Metadata'!H$2), 'Campaign Metadata'!A$2, IF( AND(C37 >= 'Campaign Metadata'!J$3, C37 <= 'Campaign Metadata'!H$3), 'Campaign Metadata'!A$3, IF( AND(C37 >= 'Campaign Metadata'!J$4, C37 <= 'Campaign Metadata'!H$4), 'Campaign Metadata'!A$4, IF( AND(C37 >= 'Campaign Metadata'!J$5, C37 <= 'Campaign Metadata'!H$5), 'Campaign Metadata'!A$5, "Outside Campaign" )))) -> SummerSplash | E37: Reel | F37: Check out our latest reel on facebook! | G37: 3960 | H37: 266 | I37: 8 | J37: 35640 | K37: 34850 | L37: 208 | M37: LiveForNow | N37: ThirstyForMore | O37: BetterWithPepsi | P37: 0.1187991 | Q37: =DATEVALUE(C37) -> 45531 | R37: =G37 + H37 + I37 -> 4234 | S37: =IF(D37="Outside Campaign","Before Campaign","During Campaign") -> During Campaign | T37: =IF(B37=B36, K37-K36, 0) -> -1957 | U37: =ISOWEEKNUM(C37) -> 35
A38: P222 | B38: FACEBOOK | C38: 45573 | D38: =IF( AND(C38 >= 'Campaign Metadata'!J$2, C38 <= 'Campaign Metadata'!H$2), 'Campaign Metadata'!A$2, IF( AND(C38 >= 'Campaign Metadata'!J$3, C38 <= 'Campaign Metadata'!H$3), 'Campaign Metadata'!A$3, IF( AND(C38 >= 'Campaign Metadata'!J$4, C38 <= 'Campaign Metadata'!H$4), 'Campaign Metadata'!A$4, IF( AND(C38 >= 'Campaign Metadata'!J$5, C38 <= 'Campaign Metadata'!H$5), 'Campaign Metadata'!A$5, "Outside Campaign" )))) -> FestiveRadiance | E38: Reel | F38: Check out our latest reel on facebook! | G38: 1814 | H38: 653 | I38: 363 | J38: 25396 | K38: 25286 | L38: 39 | M38: LiveForNow | N38: SmoothLikeNitroPepsi | P38: 0.11143487 | Q38: =DATEVALUE(C38) -> 45573 | R38: =G38 + H38 + I38 -> 2830 | S38: =IF(D38="Outside Campaign","Before Campaign","During Campaign") -> During Campaign | T38: =IF(B38=B37, K38-K37, 0) -> -9564 | U38: =ISOWEEKNUM(C38) -> 41
A39: P156 | B39: FACEBOOK | C39: 45587 | D39: =IF( AND(C39 >= 'Campaign Metadata'!J$2, C39 <= 'Campaign Metadata'!H$2), 'Campaign Metadata'!A$2, IF( AND(C39 >= 'Campaign Metadata'!J$3, C39 <= 'Campaign Metadata'!H$3), 'Campaign Metadata'!A$3, IF( AND(C39 >= 'Campaign Metadata'!J$4, C39 <= 'Campaign Metadata'!H$4), 'Campaign Metadata'!A$4, IF( AND(C39 >= 'Campaign Metadata'!J$5, C39 <= 'Campaign Metadata'!H$5), 'Campaign Metadata'!A$5, "Outside Campaign" )))) -> FestiveRadiance | E39: Carousel | F39: Check out our latest carousel on facebook! | G39: 3352 | H39: 941 | I39: 482 | J39: 43576 | K39: 43338 | L39: 240 | M39: LiveForNow | P39: 0.10957867 | Q39: =DATEVALUE(C39) -> 45587 | R39: =G39 + H39 + I39 -> 4775 | S39: =IF(D39="Outside Campaign","Before Campaign","During Campaign") -> During Campaign | T39: =IF(B39=B38, K39-K38, 0) -> 18052 | U39: =ISOWEEKNUM(C39) -> 43
A40: P182 | B40: FACEBOOK | C40: 45504 | D40: =IF( AND(C40 >= 'Campaign Metadata'!J$2, C40 <= 'Campaign Metadata'!H$2), 'Campaign Metadata'!A$2, IF( AND(C40 >= 'Campaign Metadata'!J$3, C40 <= 'Campaign Metadata'!H$3), 'Campaign Metadata'!A$3, IF( AND(C40 >= 'Campaign Metadata'!J$4, C40 <= 'Campaign Metadata'!H$4), 'Campaign Metadata'!A$4, IF( AND(C40 >= 'Campaign Metadata'!J$5, C40 <= 'Campaign Metadata'!H$5), 'Campaign Metadata'!A$5, "Outside Campaign" )))) -> SummerSplash | E40: Image | F40: Check out our latest image on facebook! | G40: 4689 | H40: 134 | I40: 403 | J40: 51579 | K40: 50924 | L40: 173 | M40: PepsiCoRefresh | P40: 0.1013203 | Q40: =DATEVALUE(C40) -> 45504 | R40: =G40 + H40 + I40 -> 5226 | S40: =IF(D40="Outside Campaign","Before Campaign","During Campaign") -> During Campaign | T40: =IF(B40=B39, K40-K39, 0) -> 7586 | U40: =ISOWEEKNUM(C40) -> 31
A41: P266 | B41: FACEBOOK | C41: 45621 | D41: =IF( AND(C41 >= 'Campaign Metadata'!J$2, C41 <= 'Campaign Metadata'!H$2), 'Campaign Metadata'!A$2, IF( AND(C41 >= 'Campaign Metadata'!J$3, C41 <= 'Campaign Metadata'!H$3), 'Campaign Metadata'!A$3, IF( AND(C41 >= 'Campaign Metadata'!J$4, C41 <= 'Campaign Metadata'!H$4), 'Campaign Metadata'!A$4, IF( AND(C41 >= 'Campaign Metadata'!J$5, C41 <= 'Campaign Metadata'!H$5), 'Campaign Metadata'!A$5, "Outside Campaign" )))) -> FestiveRadiance | E41: Story | F41: Check out our latest story on facebook! | G41: 4182 | H41: 640 | I41: 240 | J41: 50184 | K41: 49351 | L41: 10 | M41: PepsiCoRefresh | P41: 0.1008688 | Q41: =DATEVALUE(C41) -> 45621 | R41: =G41 + H41 + I41 -> 5062 | S41: =IF(D41="Outside Campaign","Before Campaign","During Campaign") -> During Campaign | T41: =IF(B41=B40, K41-K40, 0) -> -1573 | U41: =ISOWEEKNUM(C41) -> 48
A42: P103 | B42: FACEBOOK | C42: 45454 | D42: =IF( AND(C42 >= 'Campaign Metadata'!J$2, C42 <= 'Campaign Metadata'!H$2), 'Campaign Metadata'!A$2, IF( AND(C42 >= 'Campaign Metadata'!J$3, C42 <= 'Campaign Metadata'!H$3), 'Campaign Metadata'!A$3, IF( AND(C42 >= 'Campaign Metadata'!J$4, C42 <= 'Campaign Metadata'!H$4), 'Campaign Metadata'!A$4, IF( AND(C42 >= 'Campaign Metadata'!J$5, C42 <= 'Campaign Metadata'!H$5), 'Campaign Metadata'!A$5, "Outside Campaign" )))) -> SummerSplash | E42: Image | F42: Check out our latest image on facebook! | G42: 3689 | H42: 48 | I42: 306 | J42: 40579 | K42: 39588 | L42: 212 | M42: ThirstyForMore | P42: 0.099632815 | Q42: =DATEVALUE(C42) -> 45454 | R42: =G42 + H42 + I42 -> 4043 | S42: =IF(D42="Outside Campaign","Before Campaign","During Campaign") -> During Campaign | T42: =IF(B42=B41, K42-K41, 0) -> -9763 | U42: =ISOWEEKNUM(C42) -> 24
A43: P017 | B43: FACEBOOK | C43: 45782 | D43: =IF( AND(C43 >= 'Campaign Metadata'!J$2, C43 <= 'Campaign Metadata'!H$2), 'Campaign Metadata'!A$2, IF( AND(C43 >= 'Campaign Metadata'!J$3, C43 <= 'Campaign Metadata'!H$3), 'Campaign Metadata'!A$3, IF( AND(C43 >= 'Campaign Metadata'!J$4, C43 <= 'Campaign Metadata'!H$4), 'Campaign Metadata'!A$4, IF( AND(C43 >= 'Campaign Metadata'!J$5, C43 <= 'Campaign Metadata'!H$5), 'Campaign Metadata'!A$5, "Outside Campaign" )))) -> Outside Campaign | E43: Text | F43: Check out our latest text on facebook! | G43: 4441 | H43: 511 | I43: 70 | J43: 53292 | K43: 53082 | L43: 159 | M43: ThirstyForMore | P43: 0.094235533 | Q43: =DATEVALUE(C43) -> 45782 | R43: =G43 + H43 + I43 -> 5022 | S43: =IF(D43="Outside Campaign","Before Campaign","During Campaign") -> Before Campaign | T43: =IF(B43=B42, K43-K42, 0) -> 13494 | U43: =ISOWEEKNUM(C43) -> 19
A44: P055 | B44: FACEBOOK | C44: 45460 | D44: =IF( AND(C44 >= 'Campaign Metadata'!J$2, C44 <= 'Campaign Metadata'!H$2), 'Campaign Metadata'!A$2, IF( AND(C44 >= 'Campaign Metadata'!J$3, C44 <= 'Campaign Metadata'!H$3), 'Campaign Metadata'!A$3, IF( AND(C44 >= 'Campaign Metadata'!J$4, C44 <= 'Campaign Metadata'!H$4), 'Campaign Metadata'!A$4, IF( AND(C44 >= 'Campaign Metadata'!J$5, C44 <= 'Campaign Metadata'!H$5), 'Campaign Metadata'!A$5, "Outside Campaign" )))) -> SummerSplash | E44: Image | F44: Check out our latest image on facebook! | G44: 1226 | H44: 119 | I44: 7 | J44: 14712 | K44: 14049 | L44: 123 | M44: ThirstyForMore | P44: 0.091897771 | Q44: =DATEVALUE(C44) -> 45460 | R44: =G44 + H44 + I44 -> 1352 | S44: =IF(D44="Outside Campaign","Before Campaign","During Campaign") -> During Campaign | T44: =IF(B44=B43, K44-K43, 0) -> -39033 | U44: =ISOWEEKNUM(C44) -> 25
A45: P009 | B45: FACEBOOK | C45: 45534 | D45: =IF( AND(C45 >= 'Campaign Metadata'!J$2, C45 <= 'Campaign Metadata'!H$2), 'Campaign Metadata'!A$2, IF( AND(C45 >= 'Campaign Metadata'!J$3, C45 <= 'Campaign Metadata'!H$3), 'Campaign Metadata'!A$3, IF( AND(C45 >= 'Campaign Metadata'!J$4, C45 <= 'Campaign Metadata'!H$4), 'Campaign Metadata'!A$4, IF( AND(C45 >= 'Campaign Metadata'!J$5, C45 <= 'Campaign Metadata'!H$5), 'Campaign Metadata'!A$5, "Outside Campaign" )))) -> SummerSplash | E45: Text | F45: Check out our latest text on facebook! | G45: 3784 | H45: 808 | I45: 404 | J45: 56760 | K45: 56343 | L45: 131 | M45: PepsiCoRefresh | P45: 0.088019732 | Q45: =DATEVALUE(C45) -> 45534 | R45: =G45 + H45 + I45 -> 4996 | S45: =IF(D45="Outside Campaign","Before Campaign","During Campaign") -> During Campaign | T45: =IF(B45=B44, K45-K44, 0) -> 42294 | U45: =ISOWEEKNUM(C45) -> 35
A46: P084 | B46: FACEBOOK | C46: 45635 | D46: =IF( AND(C46 >= 'Campaign Metadata'!J$2, C46 <= 'Campaign Metadata'!H$2), 'Campaign Metadata'!A$2, IF( AND(C46 >= 'Campaign Metadata'!J$3, C46 <= 'Campaign Metadata'!H$3), 'Campaign Metadata'!A$3, IF( AND(C46 >= 'Campaign Metadata'!J$4, C46 <= 'Campaign Metadata'!H$4), 'Campaign Metadata'!A$4, IF( AND(C46 >= 'Campaign Metadata'!J$5, C46 <= 'Campaign Metadata'!H$5), 'Campaign Metadata'!A$5, "Outside Campaign" )))) -> FestiveRadiance | E46: Image | F46: Check out our latest image on facebook! | G46: 1841 | H46: 851 | I46: 342 | J46: 34979 | K46: 34154 | L46: 255 | M46: LiveForNow | P46: 0.086737757 | Q46: =DATEVALUE(C46) -> 45635 | R46: =G46 + H46 + I46 -> 3034 | S46: =IF(D46="Outside Campaign","Before Campaign","During Campaign") -> During Campaign | T46: =IF(B46=B45, K46-K45, 0) -> -22189 | U46: =ISOWEEKNUM(C46) -> 50
A47: P162 | B47: FACEBOOK | C47: 45748 | D47: =IF( AND(C47 >= 'Campaign Metadata'!J$2, C47 <= 'Campaign Metadata'!H$2), 'Campaign Metadata'!A$2, IF( AND(C47 >= 'Campaign Metadata'!J$3, C47 <= 'Campaign Metadata'!H$3), 'Campaign Metadata'!A$3, IF( AND(C47 >= 'Campaign Metadata'!J$4, C47 <= 'Campaign Metadata'!H$4), 'Campaign Metadata'!A$4, IF( AND(C47 >= 'Campaign Metadata'!J$5, C47 <= 'Campaign Metadata'!H$5), 'Campaign Metadata'!A$5, "Outside Campaign" )))) -> Outside Campaign | E47: Story | F47: Check out our latest story on facebook! | G47: 3430 | H47: 566 | I47: 164 | J47: 48020 | K47: 47305 | L47: 120 | M47: LiveForNow | P47: 0.086630571 | Q47: =DATEVALUE(C47) -> 45748 | R47: =G47 + H47 + I47 -> 4160 | S47: =IF(D47="Outside Campaign","Before Campaign","During Campaign") -> Before Campaign | T47: =IF(B47=B46, K47-K46, 0) -> 13151 | U47: =ISOWEEKNUM(C47) -> 14
A48: P186 | B48: FACEBOOK | C48: 45528 | D48: =IF( AND(C48 >= 'Campaign Metadata'!J$2, C48 <= 'Campaign Metadata'!H$2), 'Campaign Metadata'!A$2, IF( AND(C48 >= 'Campaign Metadata'!J$3, C48 <= 'Campaign Metadata'!H$3), 'Campaign Metadata'!A$3, IF( AND(C48 >= 'Campaign Metadata'!J$4, C48 <= 'Campaign Metadata'!H$4), 'Campaign Metadata'!A$4, IF( AND(C48 >= 'Campaign Metadata'!J$5, C48 <= 'Campaign Metadata'!H$5), 'Campaign Metadata'!A$5, "Outside Campaign" )))) -> SummerSplash | E48: Carousel | F48: Check out our latest carousel on facebook! | G48: 4292 | H48: 51 | I48: 392 | J48: 55796 | K48: 54826 | L48: 264 | M48: ThirstyForMore | P48: 0.084862714 | Q48: =DATEVALUE(C48) -> 45528 | R48: =G48 + H48 + I48 -> 4735 | S48: =IF(D48="Outside Campaign","Before Campaign","During Campaign") -> During Campaign | T48: =IF(B48=B47, K48-K47, 0) -> 7521 | U48: =ISOWEEKNUM(C48) -> 34
...

Sheet Vedio link
A1: Video Link
A2: https://drive.google.com/file/d/1Iif33WYpArPZwY1hlmqILMIdPJ4vEkmL/view?usp=sharing

Sheet Hashtag_Long
A1: Post ID | B1: Clicks | C1: Hashtag | D1: Likes | E1: Comments
A2: P220 | B2: 12 | C2: ThirstyForMore | D2: =VLOOKUP(A2, Posts!A:H, 7, FALSE) -> 84 | E2: =VLOOKUP(A2, Posts!A:I, 8, FALSE) -> 897
A3: P058 | B3: 262 | C3: PepsiCoRefresh | D3: =VLOOKUP(A3, Posts!A:H, 7, FALSE) -> 103 | E3: =VLOOKUP(A3, Posts!A:I, 8, FALSE) -> 770
A4: P232 | B4: 201 | C4: ThirstyForMore | D4: =VLOOKUP(A4, Posts!A:H, 7, FALSE) -> 249 | E4: =VLOOKUP(A4, Posts!A:I, 8, FALSE) -> 592
A5: P178 | B5: 238 | C5: PepsiCoRefresh | D5: =VLOOKUP(A5, Posts!A:H, 7, FALSE) -> 129 | E5: =VLOOKUP(A5, Posts!A:I, 8, FALSE) -> 643
A6: P175 | B6: 154 | C6: LiveForNow | D6: =VLOOKUP(A6, Posts!A:H, 7, FALSE) -> 142 | E6: =VLOOKUP(A6, Posts!A:I, 8, FALSE) -> 784
A7: P062 | B7: 148 | C7: PepsiCoRefresh | D7: =VLOOKUP(A7, Posts!A:H, 7, FALSE) -> 53 | E7: =VLOOKUP(A7, Posts!A:I, 8, FALSE) -> 81
A8: P264 | B8: 293 | C8: PepsiCoRefresh | D8: =VLOOKUP(A8, Posts!A:H, 7, FALSE) -> 59 | E8: =VLOOKUP(A8, Posts!A:I, 8, FALSE) -> 163
A9: P143 | B9: 117 | C9: PepsiCoRefresh | D9: =VLOOKUP(A9, Posts!A:H, 7, FALSE) -> 80 | E9: =VLOOKUP(A9, Posts!A:I, 8, FALSE) -> 362
A10: P210 | B10: 287 | C10: LiveForNow | D10: =VLOOKUP(A10, Posts!A:H, 7, FALSE) -> 257 | E10: =VLOOKUP(A10, Posts!A:I, 8, FALSE) -> 966
A11: P070 | B11: 43 | C11: PepsiCoRefresh | D11: =VLOOKUP(A11, Posts!A:H, 7, FALSE) -> 199 | E11: =VLOOKUP(A11, Posts!A:I, 8, FALSE) -> 772
A12: P214 | B12: 282 | C12: LiveForNow | D12: =VLOOKUP(A12, Posts!A:H, 7, FALSE) -> 521 | E12: =VLOOKUP(A12, Posts!A:I, 8, FALSE) -> 746
A13: P053 | B13: 11 | C13: ThirstyForMore | D13: =VLOOKUP(A13, Posts!A:H, 7, FALSE) -> 804 | E13: =VLOOKUP(A13, Posts!A:I, 8, FALSE) -> 639
... A340: P257 | B340: 25 | C340: BetterWithPepsi | D340: =VLOOKUP(A340, Posts!A:H, 7, FALSE) -> 3090 | E340: =VLOOKUP(A340, Posts!A:I, 8, FALSE) -> 697

Sheet Engagement Summary
A1: Week_Start_Date | B1: Platform | C1: New_Followers | D1: Unfollows | E1: Total_Followers | F1: Engagement_Rate | G1: Ad_Spend
A2: 2024-06-03 | B2: Instagram | C2: 1135 | D2: 88 | E2: 344084 | F2: 8.06 | G2: 5904
A3: 2024-06-03 | B3: Facebook | C3: 1312 | D3: 310 | E3: 42654 | F3: 4.98 | G3: 9566
A4: 2024-06-03 | B4: Twitter | C4: 584 | D4: 169 | E4: 146834 | F4: 8.31 | G4: 26752
A5: 2024-06-03 | B5: YouTube | C5: 1535 | D5: 445 | E5: 395536 | F5: 4.11 | G5: 30671
A6: 2024-06-10 | B6: Instagram | C6: 656 | D6: 139 | E6: 49157 | F6: 9.05 | G6: 9920
A7: 2024-06-10 | B7: Facebook | C7: 1697 | D7: 414 | E7: 316555 | F7: 2.37 | G7: 7924
A8: 2024-06-10 | B8: Twitter | C8: 436 | D8: 250 | E8: 254347 | F8: 4.01 | G8: 8912
A9: 2024-06-10 | B9: YouTube | C9: 1197 | D9: 203 | E9: 413878 | F9: 3.16 | G9: 21205
A10: 2024-06-17 | B10: Instagram | C10: 1048 | D10: 155 | E10: 456946 | F10: 2.46 | G10: 11329
A11: 2024-06-17 | B11: Facebook | C11: 1753 | D11: 371 | E11: 169496 | F11: 8.11 | G11: 46670
A12: 2024-06-17 | B12: Twitter | C12: 1335 | D12: 40 | E12: 122732 | F12: 8.19 | G12: 22482
A13: 2024-06-17 | B13: YouTube | C13: 403 | D13: 66 | E13: 382851 | F13: 3.49 | G13: 24313
... A201: 2025-05-12 | B201: YouTube | C201: 119 | D201: 456 | E201: 82558 | F201: 6.81 | G201: 12174

Sheet Avg_Engagement_by_Platform

Sheet Pivot_Content_Platform

Sheet Avg_Clicks_by_Hashtag
C1: Rank
C2: =RANK(B2,$B$2:$B$7,0) -> 1
C3: =RANK(B3,$B$2:$B$7,0) -> 5
C4: =RANK(B4,$B$2:$B$7,0) -> 4
C5: =RANK(B5,$B$2:$B$7,0) -> 2
C6: =RANK(B6,$B$2:$B$7,0) -> 6
C7: =RANK(B7,$B$2:$B$7,0) -> 3

Sheet Most frequently used hashtags

Sheet Avg_Growth_by_Platform

Sheet Engagement_vs_AdSpend

Sheet Task 3 - Conclusion
A1: Task 3 – Part 4: Platform Strategy Recommendation
A2: Based on the analysis done in Task 3, we can clearly see that all platforms are not performing equally. From the average engagement rate analysis, Instagram has the highest engagement rate, followed closely by Twitter. Facebook and YouTube show comparatively lower engagement levels than these two platforms. From the growth rate analysis using average new followers, Instagram again shows the highest follower growth, and Twitter also performs well. This indicates that these platforms are not only engaging users better but are also growing their audience faster. From the engagement versus ad spend analysis, we can observe that Instagram gives good engagement even with moderate ad spend, which makes it more cost-effective. Some platforms spend more on ads but do not receive proportionally higher engagement in return. Therefore, it is better for the company to focus mainly on 1–2 core platforms, especially Instagram and Twitter, instead of spreading the budget equally across all platforms. By focusing more on these high-performing platforms, the company can achieve: -Higher engagement -Better return on ad spend -Faster follower growth However, the company should still maintain a presence on other platforms like Facebook and YouTube, but with lower budget and lower priority, mainly for brand visibility. Conclusion: The best strategy is to focus primarily on Instagram and Twitter as core platforms, while maintaining a limited multi-platform presence to ensure overall brand reach and visibility.

Sheet Content_vs_Platform

Sheet Task 4 – Content Strategy Recom
A1: Task 4 – Part 3: Content Type Strategy Recommendation
A2: Based on the content vs platform analysis, we can see that different platforms perform better with different content types. On Instagram, Reels and Carousels show the highest average likes and comments compared to Images, Stories, and Text posts. This indicates that Instagram users prefer more visual and interactive content. Therefore, Instagram should prioritize Reels and Carousels to maximize engagement. On Facebook, Carousels and Stories perform better than other content types. These formats attract more user interaction in terms of likes and comments. Hence, Facebook should focus more on Carousel posts and Stories for better performance. On YouTube, Videos (Reels/Video content) clearly perform the best, with higher average engagement compared to Images and Text. This is expected because YouTube is primarily a video-based platform. Therefore, YouTube should prioritize Video content as the main content type. Overall, the content strategy should be platform-specific: -Instagram: Focus mainly on Reels and Carousels -Facebook: Focus on Carousels and Stories -YouTube: Strongly prioritize Video content This platform-wise content strategy will help improve engagement and make better use of content creation efforts.

Sheet Campaign Metadata
A1: Campaign_Name | B1: Start_Date | C1: End_Date | D1: Objective | E1: Total_Budget | F1: Target_Platforms | G1: Primary_Hashtags | H1: =DATEVALUE(TEXT(B2,"mm/dd/yyyy")) -> 45458 | I1: =DATEVALUE(TEXT(C2,"mm/dd/yyyy")) -> 45488
A2: SummerSplash | B2: 45458 | C2: 45488 | D2: Brand Awareness | E2: 150000 | F2: Instagram,Facebook | G2: #ThirstyForMore,#PepsiCoRefresh | H2: =DATEVALUE(TEXT(B3,"mm/dd/yyyy")) -> 45566 | I2: =DATEVALUE(TEXT(C3,"mm/dd/yyyy")) -> 45596
A3: FestiveRadiance | B3: 45566 | C3: 45596 | D3: Engagement | E3: 200000 | F3: Instagram,YouTube | G3: #AnytimeIsPepsiTime, | H3: =DATEVALUE(TEXT(B4,"mm/dd/yyyy")) -> 45651 | I3: =DATEVALUE(TEXT(C4,"mm/dd/yyyy")) -> 45667
A4: NewYearRefresh | B4: 45651 | C4: 45667 | D4: Product Launch | E4: 250000 | F4: Facebook,Twitter | G4: #SmoothLikeNitroPepsi | H4: =DATEVALUE(TEXT(B5,"mm/dd/yyyy")) -> 45717 | I4: =DATEVALUE(TEXT(C5,"mm/dd/yyyy")) -> 45747
A5: DailyWellness | B5: 45717 | C5: 45747 | D5: Traffic | E5: 180000 | F5: Instagram,Twitter | G5: #BetterWithPepsi,#LiveForNow | H5: =DATEVALUE(TEXT(B6,"mm/dd/yyyy")) -> 0 | I5: =DATEVALUE(TEXT(C6,"mm/dd/yyyy")) -> 0

Sheet Campaign_Performance

Sheet Campaign_Engagement_Uplift
E2: Engagement_Uplift_%
E3: =IFERROR( (C3 - B3) / B3 , 0 ) -> 0
E4: =IFERROR( (C4 - B4) / B4 , 0 ) -> 0
E5: =IFERROR( (C5 - B5) / B5 , 0 ) -> -1
E6: =IFERROR( (C6 - B6) / B6 , 0 ) -> 0
E7: =IFERROR( (C7 - B7) / B7 , 0 ) -> 2.4496197

Sheet Highest ROI (Engagement vs Budg
A1: Campaign_Name | B1: Total_Engagement | C1: Total_Budget | D1: ROI
A2: SummerSplash | B2: =VLOOKUP(A2, Campaign_Performance!A:D, 4, FALSE) -> 283492 | C2: =VLOOKUP(A2, 'Campaign Metadata'!A:E, 5, FALSE) -> 150000 | D2: =IFERROR(B2 / C2, "") -> 1.8899467
A3: FestiveRadiance | B3: =VLOOKUP(A3, Campaign_Performance!A:D, 4, FALSE) -> 236043 | C3: =VLOOKUP(A3, 'Campaign Metadata'!A:E, 5, FALSE) -> 200000 | D3: =IFERROR(B3 / C3, "") -> 1.180215
A4: NewYearRefresh | B4: =VLOOKUP(A4, Campaign_Performance!A:D, 4, FALSE) -> 117077 | C4: =VLOOKUP(A4, 'Campaign Metadata'!A:E, 5, FALSE) -> 250000 | D4: =IFERROR(B4 / C4, "") -> 0.468308

Sheet Follower_Growth_Impact

Sheet Weekly_Follower_Growth_Trends

Sheet Weekly_Max_Follower_Gain

Sheet Moving_Average_Follower_Growth
A1: Week | B1: Follower_Growth | C1: Moving_Avg_3_Weeks
A2: 1 | B2: -5399
A3: 2 | B3: 16004
A4: 3 | B4: -73869 | C4: =AVERAGE(B2:B4) -> -21088
A5: 4 | B5: -15928 | C5: =AVERAGE(B3:B5) -> -24597.667
A6: 5 | B6: 25234 | C6: =AVERAGE(B4:B6) -> -21521
A7: 6 | B7: 17670 | C7: =AVERAGE(B5:B7) -> 8992
A8: 7 | B8: 22964 | C8: =AVERAGE(B6:B8) -> 21956
A9: 8 | B9: 48821 | C9: =AVERAGE(B7:B9) -> 29818.333
A10: 9 | B10: -34815 | C10: =AVERAGE(B8:B10) -> 12323.333
A11: 10 | B11: -50262 | C11: =AVERAGE(B9:B11) -> -12085.333
A12: 11 | B12: -30038 | C12: =AVERAGE(B10:B12) -> -38371.667
A13: 12 | B13: -19810 | C13: =AVERAGE(B11:B13) -> -33370
A14: 13 | B14: 52830 | C14: =AVERAGE(B12:B14) -> 994
A15: 14 | B15: 33755 | C15: =AVERAGE(B13:B15) -> 22258.333
... A52: 52 | B52: 26553 | C52: =AVERAGE(B50:B52) -> 11333.333

Sheet AdSpend_vs_FollowerGrowth
A1: Campaign_Name | B1: Total_Budget | C1: Total_Follower_Growth | E1: Correlation between Ad Spend & Follower Growth
A2: SummerSplash | B2: =IFERROR(VLOOKUP(A2, 'Campaign Metadata'!A:E, 5, FALSE), "") -> 150000 | C2: =SUMIF(Posts!D:D, A2, Posts!U:U) -> 3107 | E2: =CORREL(B2:B5, C2:C5) -> -0.4293947
A3: FestiveRadiance | B3: =IFERROR(VLOOKUP(A3, 'Campaign Metadata'!A:E, 5, FALSE), "") -> 200000 | C3: =SUMIF(Posts!D:D, A3, Posts!U:U) -> 3829
A4: NewYearRefresh | B4: =IFERROR(VLOOKUP(A4, 'Campaign Metadata'!A:E, 5, FALSE), "") -> 250000 | C4: =SUMIF(Posts!D:D, A4, Posts!U:U) -> 276
A5: DailyWellness | B5: =IFERROR(VLOOKUP(A5, 'Campaign Metadata'!A:E, 5, FALSE), "") -> 180000 | C5: =SUMIF(Posts!D:D, A5, Posts!U:U) -> 0
